Workbook

Sheet SwapDesk — Assumptions · Commer
A1: SwapDesk — Assumptions · Commercial and cost controls
A2: Financial model (4 pages) · Main Scenario
A4: Variable / dimension | B4: Value
A5: Subscription price | B5: =49 -> 49
A6: Included resolutions | B6: =100 -> 100
A7: Overage price | B7: =0.5 -> 0.5
A8: Cost per execution | B8: =0.03 -> 0.03
A9: Technical support hourly cost | B9: =25 -> 25
A10: Onboarding minutes | B10: =90 -> 90
A11: Customer acquisition cost | B11: =100 -> 100
A12: Fixed infrastructure cost | B12: =75 -> 75
A13: Infrastructure cost per store | B13: =1 -> 1
A14: Other monthly overhead | B14: =150 -> 150
A15: Opening cash assumption | B15: =15000 -> 15000
A16: Founder annual pay | B16: =24000 -> 24000

Sheet SwapDesk — Assumptions · Mercha
A1: SwapDesk — Assumptions · Merchant segment assumptions
A2: Financial model (4 pages) · Main Scenario
A4: Variable / dimension | B4: New stores per month | C4: Monthly store churn | D4: Cases per store | E4: Verified resolution rate | F4: Extra execution factor | G4: Support minutes per store
A5: Growing shop | B5: =0.5 -> 0.5 | C5: =0.02 -> 0.02 | D5: =400 -> 400 | E5: =0.65 -> 0.65 | F5: =0.15 -> 0.15 | G5: =30 -> 30
A6: Small shop | B6: =1 -> 1 | C6: =0.03 -> 0.03 | D6: =120 -> 120 | E6: =0.65 -> 0.65 | F6: =0.15 -> 0.15 | G6: =15 -> 15

Sheet SwapDesk — Assumptions · Placeh
A1: SwapDesk — Assumptions · Placeholder founder compensation
A2: Financial model (4 pages) · Main Scenario
A4: Variable / dimension | B4: Founder start date | C4: Planned annual compensation
A5: Placeholder founder 1 | B5: =DATE(2027,1,1) -> 46388 | C5: =IF('SwapDesk — Assumptions · Commer'!B16="","",'SwapDesk — Assumptions · Commer'!B16) -> 24000

Sheet SwapDesk — Assumptions · Simula
A1: SwapDesk — Assumptions · Simulator baseline rates
A2: Financial model (4 pages) · Main Scenario
A4: Variable / dimension | B4: Value
A5: Simulator resolution rate | B5: =IF('SwapDesk — Assumptions · Mercha'!E6="","",'SwapDesk — Assumptions · Mercha'!E6) -> 0.65
A6: Simulator extra execution factor | B6: =IF('SwapDesk — Assumptions · Mercha'!F6="","",'SwapDesk — Assumptions · Mercha'!F6) -> 0.15

Sheet SwapDesk — Operations · Merchan
A1: SwapDesk — Operations · Merchant and execution forecast
A2: Financial model (4 pages) · Main Scenario
A4: Variable / dimension | B4: 2026-09 | C4: 2026-10 | D4: 2026-11 | E4: 2026-12 | F4: 2027-01 | G4: 2027-02 | H4: 2027-03 | I4: 2027-04 | J4: 2027-05 | K4: 2027-06 | L4: 2027-07 | M4: 2027-08 | N4: 2027-09 | O4: 2027-10 | P4: 2027-11 | Q4: 2027-12 | R4: 2028-01 | S4: 2028-02 | T4: 2028-03 | U4: 2028-04 | V4: 2028-05 | W4: 2028-06 | X4: 2028-07 | Y4: 2028-08 | Z4: 2028-09
A5: Opening stores | B5: =SUM('SwapDesk — Operations · Merchan'!B6,'SwapDesk — Operations · Merchan'!B7) -> 0 | C5: =SUM('SwapDesk — Operations · Merchan'!C6,'SwapDesk — Operations · Merchan'!C7) -> 7 | D5: =SUM('SwapDesk — Operations · Merchan'!D6,'SwapDesk — Operations · Merchan'!D7) -> 8.31 | E5: =SUM('SwapDesk — Operations · Merchan'!E6,'SwapDesk — Operations · Merchan'!E7) -> 9.5853 | F5: =SUM('SwapDesk — Operations · Merchan'!F6,'SwapDesk — Operations · Merchan'!F7) -> 10.826849 | G5: =SUM('SwapDesk — Operations · Merchan'!G6,'SwapDesk — Operations · Merchan'!G7) -> 12.035569 | H5: =SUM('SwapDesk — Operations · Merchan'!H6,'SwapDesk — Operations · Merchan'!H7) -> 13.212358 | I5: =SUM('SwapDesk — Operations · Merchan'!I6,'SwapDesk — Operations · Merchan'!I7) -> 14.358085 | ... Z5: =SUM('SwapDesk — Operations · Merchan'!Z6,'SwapDesk — Operations · Merchan'!Z7) -> 29.819331
A6: Growing shop | B6: =0 -> 0 | C6: =IF('SwapDesk — Operations · Merchan'!B15="","",'SwapDesk — Operations · Merchan'!B15) -> 2 | D6: =IF('SwapDesk — Operations · Merchan'!C15="","",'SwapDesk — Operations · Merchan'!C15) -> 2.46 | E6: =IF('SwapDesk — Operations · Merchan'!D15="","",'SwapDesk — Operations · Merchan'!D15) -> 2.9108 | F6: =IF('SwapDesk — Operations · Merchan'!E15="","",'SwapDesk — Operations · Merchan'!E15) -> 3.352584 | G6: =IF('SwapDesk — Operations · Merchan'!F15="","",'SwapDesk — Operations · Merchan'!F15) -> 3.7855323 | H6: =IF('SwapDesk — Operations · Merchan'!G15="","",'SwapDesk — Operations · Merchan'!G15) -> 4.2098217 | I6: =IF('SwapDesk — Operations · Merchan'!H15="","",'SwapDesk — Operations · Merchan'!H15) -> 4.6256252 | J6: =IF('SwapDesk — Operations · Merchan'!I15="","",'SwapDesk — Operations · Merchan'!I15) -> 5.0331127 | ... Z6: =IF('SwapDesk — Operations · Merchan'!Y15="","",'SwapDesk — Operations · Merchan'!Y15) -> 10.548013
A7: Small shop | B7: =0 -> 0 | C7: =IF('SwapDesk — Operations · Merchan'!B16="","",'SwapDesk — Operations · Merchan'!B16) -> 5 | D7: =IF('SwapDesk — Operations · Merchan'!C16="","",'SwapDesk — Operations · Merchan'!C16) -> 5.85 | E7: =IF('SwapDesk — Operations · Merchan'!D16="","",'SwapDesk — Operations · Merchan'!D16) -> 6.6745 | F7: =IF('SwapDesk — Operations · Merchan'!E16="","",'SwapDesk — Operations · Merchan'!E16) -> 7.474265 | G7: =IF('SwapDesk — Operations · Merchan'!F16="","",'SwapDesk — Operations · Merchan'!F16) -> 8.250037 | H7: =IF('SwapDesk — Operations · Merchan'!G16="","",'SwapDesk — Operations · Merchan'!G16) -> 9.0025359 | I7: =IF('SwapDesk — Operations · Merchan'!H16="","",'SwapDesk — Operations · Merchan'!H16) -> 9.7324599 | J7: =IF('SwapDesk — Operations · Merchan'!I16="","",'SwapDesk — Operations · Merchan'!I16) -> 10.440486 | ... Z7: =IF('SwapDesk — Operations · Merchan'!Y16="","",'SwapDesk — Operations · Merchan'!Y16) -> 19.271318
A8: New stores | B8: =SUM('SwapDesk — Operations · Merchan'!B9,'SwapDesk — Operations · Merchan'!B10) -> 0 | C8: =SUM('SwapDesk — Operations · Merchan'!C9,'SwapDesk — Operations · Merchan'!C10) -> 1.5 | D8: =SUM('SwapDesk — Operations · Merchan'!D9,'SwapDesk — Operations · Merchan'!D10) -> 1.5 | E8: =SUM('SwapDesk — Operations · Merchan'!E9,'SwapDesk — Operations · Merchan'!E10) -> 1.5 | F8: =SUM('SwapDesk — Operations · Merchan'!F9,'SwapDesk — Operations · Merchan'!F10) -> 1.5 | G8: =SUM('SwapDesk — Operations · Merchan'!G9,'SwapDesk — Operations · Merchan'!G10) -> 1.5 | H8: =SUM('SwapDesk — Operations · Merchan'!H9,'SwapDesk — Operations · Merchan'!H10) -> 1.5 | I8: =SUM('SwapDesk — Operations · Merchan'!I9,'SwapDesk — Operations · Merchan'!I10) -> 1.5 | ... Z8: =SUM('SwapDesk — Operations · Merchan'!Z9,'SwapDesk — Operations · Merchan'!Z10) -> 1.5
A9: Growing shop | B9: =0 -> 0 | C9: =IF('SwapDesk — Assumptions · Mercha'!B5="","",'SwapDesk — Assumptions · Mercha'!B5) -> 0.5 | D9: =IF('SwapDesk — Assumptions · Mercha'!B5="","",'SwapDesk — Assumptions · Mercha'!B5) -> 0.5 | E9: =IF('SwapDesk — Assumptions · Mercha'!B5="","",'SwapDesk — Assumptions · Mercha'!B5) -> 0.5 | F9: =IF('SwapDesk — Assumptions · Mercha'!B5="","",'SwapDesk — Assumptions · Mercha'!B5) -> 0.5 | G9: =IF('SwapDesk — Assumptions · Mercha'!B5="","",'SwapDesk — Assumptions · Mercha'!B5) -> 0.5 | H9: =IF('SwapDesk — Assumptions · Mercha'!B5="","",'SwapDesk — Assumptions · Mercha'!B5) -> 0.5 | I9: =IF('SwapDesk — Assumptions · Mercha'!B5="","",'SwapDesk — Assumptions · Mercha'!B5) -> 0.5 | J9: =IF('SwapDesk — Assumptions · Mercha'!B5="","",'SwapDesk — Assumptions · Mercha'!B5) -> 0.5 | K9: =IF('SwapDesk — Assumptions · Mercha'!B5="","",'SwapDesk — Assumptions · Mercha'!B5) -> 0.5 | L9: =IF('SwapDesk — Assumptions · Mercha'!B5="","",'SwapDesk — Assumptions · Mercha'!B5) -> 0.5 | M9: =IF('SwapDesk — Assumptions · Mercha'!B5="","",'SwapDesk — Assumptions · Mercha'!B5) -> 0.5 | N9: =IF('SwapDesk — Assumptions · Mercha'!B5="","",'SwapDesk — Assumptions · Mercha'!B5) -> 0.5 | O9: =IF('SwapDesk — Assumptions · Mercha'!B5="","",'SwapDesk — Assumptions · Mercha'!B5) -> 0.5 | P9: =IF('SwapDesk — Assumptions · Mercha'!B5="","",'SwapDesk — Assumptions · Mercha'!B5) -> 0.5 | Q9: =IF('SwapDesk — Assumptions · Mercha'!B5="","",'SwapDesk — Assumptions · Mercha'!B5) -> 0.5 | R9: =IF('SwapDesk — Assumptions · Mercha'!B5="","",'SwapDesk — Assumptions · Mercha'!B5) -> 0.5 | S9: =IF('SwapDesk — Assumptions · Mercha'!B5="","",'SwapDesk — Assumptions · Mercha'!B5) -> 0.5 | T9: =IF('SwapDesk — Assumptions · Mercha'!B5="","",'SwapDesk — Assumptions · Mercha'!B5) -> 0.5 | U9: =IF('SwapDesk — Assumptions · Mercha'!B5="","",'SwapDesk — Assumptions · Mercha'!B5) -> 0.5 | V9: =IF('SwapDesk — Assumptions · Mercha'!B5="","",'SwapDesk — Assumptions · Mercha'!B5) -> 0.5 | W9: =IF('SwapDesk — Assumptions · Mercha'!B5="","",'SwapDesk — Assumptions · Mercha'!B5) -> 0.5 | X9: =IF('SwapDesk — Assumptions · Mercha'!B5="","",'SwapDesk — Assumptions · Mercha'!B5) -> 0.5 | Y9: =IF('SwapDesk — Assumptions · Mercha'!B5="","",'SwapDesk — Assumptions · Mercha'!B5) -> 0.5 | Z9: =IF('SwapDesk — Assumptions · Mercha'!B5="","",'SwapDesk — Assumptions · Mercha'!B5) -> 0.5
A10: Small shop | B10: =0 -> 0 | C10: =IF('SwapDesk — Assumptions · Mercha'!B6="","",'SwapDesk — Assumptions · Mercha'!B6) -> 1 | D10: =IF('SwapDesk — Assumptions · Mercha'!B6="","",'SwapDesk — Assumptions · Mercha'!B6) -> 1 | E10: =IF('SwapDesk — Assumptions · Mercha'!B6="","",'SwapDesk — Assumptions · Mercha'!B6) -> 1 | F10: =IF('SwapDesk — Assumptions · Mercha'!B6="","",'SwapDesk — Assumptions · Mercha'!B6) -> 1 | G10: =IF('SwapDesk — Assumptions · Mercha'!B6="","",'SwapDesk — Assumptions · Mercha'!B6) -> 1 | H10: =IF('SwapDesk — Assumptions · Mercha'!B6="","",'SwapDesk — Assumptions · Mercha'!B6) -> 1 | I10: =IF('SwapDesk — Assumptions · Mercha'!B6="","",'SwapDesk — Assumptions · Mercha'!B6) -> 1 | J10: =IF('SwapDesk — Assumptions · Mercha'!B6="","",'SwapDesk — Assumptions · Mercha'!B6) -> 1 | K10: =IF('SwapDesk — Assumptions · Mercha'!B6="","",'SwapDesk — Assumptions · Mercha'!B6) -> 1 | L10: =IF('SwapDesk — Assumptions · Mercha'!B6="","",'SwapDesk — Assumptions · Mercha'!B6) -> 1 | M10: =IF('SwapDesk — Assumptions · Mercha'!B6="","",'SwapDesk — Assumptions · Mercha'!B6) -> 1 | N10: =IF('SwapDesk — Assumptions · Mercha'!B6="","",'SwapDesk — Assumptions · Mercha'!B6) -> 1 | O10: =IF('SwapDesk — Assumptions · Mercha'!B6="","",'SwapDesk — Assumptions · Mercha'!B6) -> 1 | P10: =IF('SwapDesk — Assumptions · Mercha'!B6="","",'SwapDesk — Assumptions · Mercha'!B6) -> 1 | Q10: =IF('SwapDesk — Assumptions · Mercha'!B6="","",'SwapDesk — Assumptions · Mercha'!B6) -> 1 | R10: =IF('SwapDesk — Assumptions · Mercha'!B6="","",'SwapDesk — Assumptions · Mercha'!B6) -> 1 | S10: =IF('SwapDesk — Assumptions · Mercha'!B6="","",'SwapDesk — Assumptions · Mercha'!B6) -> 1 | T10: =IF('SwapDesk — Assumptions · Mercha'!B6="","",'SwapDesk — Assumptions · Mercha'!B6) -> 1 | U10: =IF('SwapDesk — Assumptions · Mercha'!B6="","",'SwapDesk — Assumptions · Mercha'!B6) -> 1 | V10: =IF('SwapDesk — Assumptions · Mercha'!B6="","",'SwapDesk — Assumptions · Mercha'!B6) -> 1 | W10: =IF('SwapDesk — Assumptions · Mercha'!B6="","",'SwapDesk — Assumptions · Mercha'!B6) -> 1 | X10: =IF('SwapDesk — Assumptions · Mercha'!B6="","",'SwapDesk — Assumptions · Mercha'!B6) -> 1 | Y10: =IF('SwapDesk — Assumptions · Mercha'!B6="","",'SwapDesk — Assumptions · Mercha'!B6) -> 1 | Z10: =IF('SwapDesk — Assumptions · Mercha'!B6="","",'SwapDesk — Assumptions · Mercha'!B6) -> 1
A11: Lost stores | B11: =SUM('SwapDesk — Operations · Merchan'!B12,'SwapDesk — Operations · Merchan'!B13) -> 0 | C11: =SUM('SwapDesk — Operations · Merchan'!C12,'SwapDesk — Operations · Merchan'!C13) -> 0.19 | D11: =SUM('SwapDesk — Operations · Merchan'!D12,'SwapDesk — Operations · Merchan'!D13) -> 0.2247 | E11: =SUM('SwapDesk — Operations · Merchan'!E12,'SwapDesk — Operations · Merchan'!E13) -> 0.258451 | F11: =SUM('SwapDesk — Operations · Merchan'!F12,'SwapDesk — Operations · Merchan'!F13) -> 0.29127963 | G11: =SUM('SwapDesk — Operations · Merchan'!G12,'SwapDesk — Operations · Merchan'!G13) -> 0.32321176 | H11: =SUM('SwapDesk — Operations · Merchan'!H12,'SwapDesk — Operations · Merchan'!H13) -> 0.35427251 | I11: =SUM('SwapDesk — Operations · Merchan'!I12,'SwapDesk — Operations · Merchan'!I13) -> 0.3844863 | ... Z11: =SUM('SwapDesk — Operations · Merchan'!Z12,'SwapDesk — Operations · Merchan'!Z13) -> 0.7890998
A12: Growing shop | B12: =0 -> 0 | C12: ='SwapDesk — Operations · Merchan'!C6*'SwapDesk — Assumptions · Mercha'!C5 -> 0.04 | D12: ='SwapDesk — Operations · Merchan'!D6*'SwapDesk — Assumptions · Mercha'!C5 -> 0.0492 | E12: ='SwapDesk — Operations · Merchan'!E6*'SwapDesk — Assumptions · Mercha'!C5 -> 0.058216 | F12: ='SwapDesk — Operations · Merchan'!F6*'SwapDesk — Assumptions · Mercha'!C5 -> 0.06705168 | G12: ='SwapDesk — Operations · Merchan'!G6*'SwapDesk — Assumptions · Mercha'!C5 -> 0.075710646 | H12: ='SwapDesk — Operations · Merchan'!H6*'SwapDesk — Assumptions · Mercha'!C5 -> 0.084196433 | I12: ='SwapDesk — Operations · Merchan'!I6*'SwapDesk — Assumptions · Mercha'!C5 -> 0.092512505 | J12: ='SwapDesk — Operations · Merchan'!J6*'SwapDesk — Assumptions · Mercha'!C5 -> 0.10066225 | K12: ='SwapDesk — Operations · Merchan'!K6*'SwapDesk — Assumptions · Mercha'!C5 -> 0.10864901 | L12: ='SwapDesk — Operations · Merchan'!L6*'SwapDesk — Assumptions · Mercha'!C5 -> 0.11647603 | M12: ='SwapDesk — Operations · Merchan'!M6*'SwapDesk — Assumptions · Mercha'!C5 -> 0.12414651 | N12: ='SwapDesk — Operations · Merchan'!N6*'SwapDesk — Assumptions · Mercha'!C5 -> 0.13166358 | O12: ='SwapDesk — Operations · Merchan'!O6*'SwapDesk — Assumptions · Mercha'!C5 -> 0.13903031 | P12: ='SwapDesk — Operations · Merchan'!P6*'SwapDesk — Assumptions · Mercha'!C5 -> 0.1462497 | Q12: ='SwapDesk — Operations · Merchan'!Q6*'SwapDesk — Assumptions · Mercha'!C5 -> 0.15332471 | R12: ='SwapDesk — Operations · Merchan'!R6*'SwapDesk — Assumptions · Mercha'!C5 -> 0.16025821 | S12: ='SwapDesk — Operations · Merchan'!S6*'SwapDesk — Assumptions · Mercha'!C5 -> 0.16705305 | T12: ='SwapDesk — Operations · Merchan'!T6*'SwapDesk — Assumptions · Mercha'!C5 -> 0.17371199 | U12: ='SwapDesk — Operations · Merchan'!U6*'SwapDesk — Assumptions · Mercha'!C5 -> 0.18023775 | V12: ='SwapDesk — Operations · Merchan'!V6*'SwapDesk — Assumptions · Mercha'!C5 -> 0.18663299 | W12: ='SwapDesk — Operations · Merchan'!W6*'SwapDesk — Assumptions · Mercha'!C5 -> 0.19290033 | X12: ='SwapDesk — Operations · Merchan'!X6*'SwapDesk — Assumptions · Mercha'!C5 -> 0.19904233 | Y12: ='SwapDesk — Operations · Merchan'!Y6*'SwapDesk — Assumptions · Mercha'!C5 -> 0.20506148 | Z12: ='SwapDesk — Operations · Merchan'!Z6*'SwapDesk — Assumptions · Mercha'!C5 -> 0.21096025
A13: Small shop | B13: =0 -> 0 | C13: ='SwapDesk — Operations · Merchan'!C7*'SwapDesk — Assumptions · Mercha'!C6 -> 0.15 | D13: ='SwapDesk — Operations · Merchan'!D7*'SwapDesk — Assumptions · Mercha'!C6 -> 0.1755 | E13: ='SwapDesk — Operations · Merchan'!E7*'SwapDesk — Assumptions · Mercha'!C6 -> 0.200235 | F13: ='SwapDesk — Operations · Merchan'!F7*'SwapDesk — Assumptions · Mercha'!C6 -> 0.22422795 | G13: ='SwapDesk — Operations · Merchan'!G7*'SwapDesk — Assumptions · Mercha'!C6 -> 0.24750111 | H13: ='SwapDesk — Operations · Merchan'!H7*'SwapDesk — Assumptions · Mercha'!C6 -> 0.27007608 | I13: ='SwapDesk — Operations · Merchan'!I7*'SwapDesk — Assumptions · Mercha'!C6 -> 0.2919738 | J13: ='SwapDesk — Operations · Merchan'!J7*'SwapDesk — Assumptions · Mercha'!C6 -> 0.31321458 | K13: ='SwapDesk — Operations · Merchan'!K7*'SwapDesk — Assumptions · Mercha'!C6 -> 0.33381814 | L13: ='SwapDesk — Operations · Merchan'!L7*'SwapDesk — Assumptions · Mercha'!C6 -> 0.3538036 | M13: ='SwapDesk — Operations · Merchan'!M7*'SwapDesk — Assumptions · Mercha'!C6 -> 0.37318949 | N13: ='SwapDesk — Operations · Merchan'!N7*'SwapDesk — Assumptions · Mercha'!C6 -> 0.39199381 | O13: ='SwapDesk — Operations · Merchan'!O7*'SwapDesk — Assumptions · Mercha'!C6 -> 0.41023399 | P13: ='SwapDesk — Operations · Merchan'!P7*'SwapDesk — Assumptions · Mercha'!C6 -> 0.42792697 | Q13: ='SwapDesk — Operations · Merchan'!Q7*'SwapDesk — Assumptions · Mercha'!C6 -> 0.44508916 | R13: ='SwapDesk — Operations · Merchan'!R7*'SwapDesk — Assumptions · Mercha'!C6 -> 0.46173649 | S13: ='SwapDesk — Operations · Merchan'!S7*'SwapDesk — Assumptions · Mercha'!C6 -> 0.47788439 | T13: ='SwapDesk — Operations · Merchan'!T7*'SwapDesk — Assumptions · Mercha'!C6 -> 0.49354786 | U13: ='SwapDesk — Operations · Merchan'!U7*'SwapDesk — Assumptions · Mercha'!C6 -> 0.50874143 | V13: ='SwapDesk — Operations · Merchan'!V7*'SwapDesk — Assumptions · Mercha'!C6 -> 0.52347918 | W13: ='SwapDesk — Operations · Merchan'!W7*'SwapDesk — Assumptions · Mercha'!C6 -> 0.53777481 | X13: ='SwapDesk — Operations · Merchan'!X7*'SwapDesk — Assumptions · Mercha'!C6 -> 0.55164156 | Y13: ='SwapDesk — Operations · Merchan'!Y7*'SwapDesk — Assumptions · Mercha'!C6 -> 0.56509232 | Z13: ='SwapDesk — Operations · Merchan'!Z7*'SwapDesk — Assumptions · Mercha'!C6 -> 0.57813955
A14: Ending stores | B14: =SUM('SwapDesk — Operations · Merchan'!B15,'SwapDesk — Operations · Merchan'!B16) -> 7 | C14: =SUM('SwapDesk — Operations · Merchan'!C15,'SwapDesk — Operations · Merchan'!C16) -> 8.31 | D14: =SUM('SwapDesk — Operations · Merchan'!D15,'SwapDesk — Operations · Merchan'!D16) -> 9.5853 | E14: =SUM('SwapDesk — Operations · Merchan'!E15,'SwapDesk — Operations · Merchan'!E16) -> 10.826849 | F14: =SUM('SwapDesk — Operations · Merchan'!F15,'SwapDesk — Operations · Merchan'!F16) -> 12.035569 | G14: =SUM('SwapDesk — Operations · Merchan'!G15,'SwapDesk — Operations · Merchan'!G16) -> 13.212358 | H14: =SUM('SwapDesk — Operations · Merchan'!H15,'SwapDesk — Operations · Merchan'!H16) -> 14.358085 | I14: =SUM('SwapDesk — Operations · Merchan'!I15,'SwapDesk — Operations · Merchan'!I16) -> 15.473599 | ... Z14: =SUM('SwapDesk — Operations · Merchan'!Z15,'SwapDesk — Operations · Merchan'!Z16) -> 30.530231
A15: Growing shop | B15: =2 -> 2 | C15: ='SwapDesk — Operations · Merchan'!C6+'SwapDesk — Operations · Merchan'!C9-'SwapDesk — Operations · Merchan'!C12 -> 2.46 | D15: ='SwapDesk — Operations · Merchan'!D6+'SwapDesk — Operations · Merchan'!D9-'SwapDesk — Operations · Merchan'!D12 -> 2.9108 | E15: ='SwapDesk — Operations · Merchan'!E6+'SwapDesk — Operations · Merchan'!E9-'SwapDesk — Operations · Merchan'!E12 -> 3.352584 | F15: ='SwapDesk — Operations · Merchan'!F6+'SwapDesk — Operations · Merchan'!F9-'SwapDesk — Operations · Merchan'!F12 -> 3.7855323 | G15: ='SwapDesk — Operations · Merchan'!G6+'SwapDesk — Operations · Merchan'!G9-'SwapDesk — Operations · Merchan'!G12 -> 4.2098217 | H15: ='SwapDesk — Operations · Merchan'!H6+'SwapDesk — Operations · Merchan'!H9-'SwapDesk — Operations · Merchan'!H12 -> 4.6256252 | I15: ='SwapDesk — Operations · Merchan'!I6+'SwapDesk — Operations · Merchan'!I9-'SwapDesk — Operations · Merchan'!I12 -> 5.0331127 | J15: ='SwapDesk — Operations · Merchan'!J6+'SwapDesk — Operations · Merchan'!J9-'SwapDesk — Operations · Merchan'!J12 -> 5.4324505 | ... Z15: ='SwapDesk — Operations · Merchan'!Z6+'SwapDesk — Operations · Merchan'!Z9-'SwapDesk — Operations · Merchan'!Z12 -> 10.837052
A16: Small shop | B16: =5 -> 5 | C16: ='SwapDesk — Operations · Merchan'!C7+'SwapDesk — Operations · Merchan'!C10-'SwapDesk — Operations · Merchan'!C13 -> 5.85 | D16: ='SwapDesk — Operations · Merchan'!D7+'SwapDesk — Operations · Merchan'!D10-'SwapDesk — Operations · Merchan'!D13 -> 6.6745 | E16: ='SwapDesk — Operations · Merchan'!E7+'SwapDesk — Operations · Merchan'!E10-'SwapDesk — Operations · Merchan'!E13 -> 7.474265 | F16: ='SwapDesk — Operations · Merchan'!F7+'SwapDesk — Operations · Merchan'!F10-'SwapDesk — Operations · Merchan'!F13 -> 8.250037 | G16: ='SwapDesk — Operations · Merchan'!G7+'SwapDesk — Operations · Merchan'!G10-'SwapDesk — Operations · Merchan'!G13 -> 9.0025359 | H16: ='SwapDesk — Operations · Merchan'!H7+'SwapDesk — Operations · Merchan'!H10-'SwapDesk — Operations · Merchan'!H13 -> 9.7324599 | I16: ='SwapDesk — Operations · Merchan'!I7+'SwapDesk — Operations · Merchan'!I10-'SwapDesk — Operations · Merchan'!I13 -> 10.440486 | J16: ='SwapDesk — Operations · Merchan'!J7+'SwapDesk — Operations · Merchan'!J10-'SwapDesk — Operations · Merchan'!J13 -> 11.127271 | ... Z16: ='SwapDesk — Operations · Merchan'!Z7+'SwapDesk — Operations · Merchan'!Z10-'SwapDesk — Operations · Merchan'!Z13 -> 19.693179
A17: Attempted cases | B17: =SUM('SwapDesk — Operations · Merchan'!B18,'SwapDesk — Operations · Merchan'!B19) -> 0 | C17: =SUM('SwapDesk — Operations · Merchan'!C18,'SwapDesk — Operations · Merchan'!C19) -> 1686 | D17: =SUM('SwapDesk — Operations · Merchan'!D18,'SwapDesk — Operations · Merchan'!D19) -> 1965.26 | E17: =SUM('SwapDesk — Operations · Merchan'!E18,'SwapDesk — Operations · Merchan'!E19) -> 2237.9454 | F17: =SUM('SwapDesk — Operations · Merchan'!F18,'SwapDesk — Operations · Merchan'!F19) -> 2504.2174 | G17: =SUM('SwapDesk — Operations · Merchan'!G18,'SwapDesk — Operations · Merchan'!G19) -> 2764.233 | H17: =SUM('SwapDesk — Operations · Merchan'!H18,'SwapDesk — Operations · Merchan'!H19) -> 3018.1453 | I17: =SUM('SwapDesk — Operations · Merchan'!I18,'SwapDesk — Operations · Merchan'!I19) -> 3266.1034 | ... Z17: =SUM('SwapDesk — Operations · Merchan'!Z18,'SwapDesk — Operations · Merchan'!Z19) -> 6698.0023
A18: Growing shop | B18: =0 -> 0 | C18: ='SwapDesk — Operations · Merchan'!C15*'SwapDesk — Assumptions · Mercha'!D5 -> 984 | D18: ='SwapDesk — Operations · Merchan'!D15*'SwapDesk — Assumptions · Mercha'!D5 -> 1164.32 | E18: ='SwapDesk — Operations · Merchan'!E15*'SwapDesk — Assumptions · Mercha'!D5 -> 1341.0336 | F18: ='SwapDesk — Operations · Merchan'!F15*'SwapDesk — Assumptions · Mercha'!D5 -> 1514.2129 | G18: ='SwapDesk — Operations · Merchan'!G15*'SwapDesk — Assumptions · Mercha'!D5 -> 1683.9287 | H18: ='SwapDesk — Operations · Merchan'!H15*'SwapDesk — Assumptions · Mercha'!D5 -> 1850.2501 | I18: ='SwapDesk — Operations · Merchan'!I15*'SwapDesk — Assumptions · Mercha'!D5 -> 2013.2451 | J18: ='SwapDesk — Operations · Merchan'!J15*'SwapDesk — Assumptions · Mercha'!D5 -> 2172.9802 | K18: ='SwapDesk — Operations · Merchan'!K15*'SwapDesk — Assumptions · Mercha'!D5 -> 2329.5206 | L18: ='SwapDesk — Operations · Merchan'!L15*'SwapDesk — Assumptions · Mercha'!D5 -> 2482.9302 | M18: ='SwapDesk — Operations · Merchan'!M15*'SwapDesk — Assumptions · Mercha'!D5 -> 2633.2716 | N18: ='SwapDesk — Operations · Merchan'!N15*'SwapDesk — Assumptions · Mercha'!D5 -> 2780.6061 | O18: ='SwapDesk — Operations · Merchan'!O15*'SwapDesk — Assumptions · Mercha'!D5 -> 2924.994 | P18: ='SwapDesk — Operations · Merchan'!P15*'SwapDesk — Assumptions · Mercha'!D5 -> 3066.4941 | Q18: ='SwapDesk — Operations · Merchan'!Q15*'SwapDesk — Assumptions · Mercha'!D5 -> 3205.1643 | R18: ='SwapDesk — Operations · Merchan'!R15*'SwapDesk — Assumptions · Mercha'!D5 -> 3341.061 | S18: ='SwapDesk — Operations · Merchan'!S15*'SwapDesk — Assumptions · Mercha'!D5 -> 3474.2398 | T18: ='SwapDesk — Operations · Merchan'!T15*'SwapDesk — Assumptions · Mercha'!D5 -> 3604.755 | U18: ='SwapDesk — Operations · Merchan'!U15*'SwapDesk — Assumptions · Mercha'!D5 -> 3732.6599 | V18: ='SwapDesk — Operations · Merchan'!V15*'SwapDesk — Assumptions · Mercha'!D5 -> 3858.0067 | W18: ='SwapDesk — Operations · Merchan'!W15*'SwapDesk — Assumptions · Mercha'!D5 -> 3980.8465 | X18: ='SwapDesk — Operations · Merchan'!X15*'SwapDesk — Assumptions · Mercha'!D5 -> 4101.2296 | Y18: ='SwapDesk — Operations · Merchan'!Y15*'SwapDesk — Assumptions · Mercha'!D5 -> 4219.205 | Z18: ='SwapDesk — Operations · Merchan'!Z15*'SwapDesk — Assumptions · Mercha'!D5 -> 4334.8209
A19: Small shop | B19: =0 -> 0 | C19: ='SwapDesk — Operations · Merchan'!C16*'SwapDesk — Assumptions · Mercha'!D6 -> 702 | D19: ='SwapDesk — Operations · Merchan'!D16*'SwapDesk — Assumptions · Mercha'!D6 -> 800.94 | E19: ='SwapDesk — Operations · Merchan'!E16*'SwapDesk — Assumptions · Mercha'!D6 -> 896.9118 | F19: ='SwapDesk — Operations · Merchan'!F16*'SwapDesk — Assumptions · Mercha'!D6 -> 990.00445 | G19: ='SwapDesk — Operations · Merchan'!G16*'SwapDesk — Assumptions · Mercha'!D6 -> 1080.3043 | H19: ='SwapDesk — Operations · Merchan'!H16*'SwapDesk — Assumptions · Mercha'!D6 -> 1167.8952 | I19: ='SwapDesk — Operations · Merchan'!I16*'SwapDesk — Assumptions · Mercha'!D6 -> 1252.8583 | J19: ='SwapDesk — Operations · Merchan'!J16*'SwapDesk — Assumptions · Mercha'!D6 -> 1335.2726 | K19: ='SwapDesk — Operations · Merchan'!K16*'SwapDesk — Assumptions · Mercha'!D6 -> 1415.2144 | L19: ='SwapDesk — Operations · Merchan'!L16*'SwapDesk — Assumptions · Mercha'!D6 -> 1492.758 | M19: ='SwapDesk — Operations · Merchan'!M16*'SwapDesk — Assumptions · Mercha'!D6 -> 1567.9752 | N19: ='SwapDesk — Operations · Merchan'!N16*'SwapDesk — Assumptions · Mercha'!D6 -> 1640.936 | O19: ='SwapDesk — Operations · Merchan'!O16*'SwapDesk — Assumptions · Mercha'!D6 -> 1711.7079 | P19: ='SwapDesk — Operations · Merchan'!P16*'SwapDesk — Assumptions · Mercha'!D6 -> 1780.3567 | Q19: ='SwapDesk — Operations · Merchan'!Q16*'SwapDesk — Assumptions · Mercha'!D6 -> 1846.946 | R19: ='SwapDesk — Operations · Merchan'!R16*'SwapDesk — Assumptions · Mercha'!D6 -> 1911.5376 | S19: ='SwapDesk — Operations · Merchan'!S16*'SwapDesk — Assumptions · Mercha'!D6 -> 1974.1915 | T19: ='SwapDesk — Operations · Merchan'!T16*'SwapDesk — Assumptions · Mercha'!D6 -> 2034.9657 | U19: ='SwapDesk — Operations · Merchan'!U16*'SwapDesk — Assumptions · Mercha'!D6 -> 2093.9167 | V19: ='SwapDesk — Operations · Merchan'!V16*'SwapDesk — Assumptions · Mercha'!D6 -> 2151.0992 | W19: ='SwapDesk — Operations · Merchan'!W16*'SwapDesk — Assumptions · Mercha'!D6 -> 2206.5663 | X19: ='SwapDesk — Operations · Merchan'!X16*'SwapDesk — Assumptions · Mercha'!D6 -> 2260.3693 | Y19: ='SwapDesk — Operations · Merchan'!Y16*'SwapDesk — Assumptions · Mercha'!D6 -> 2312.5582 | Z19: ='SwapDesk — Operations · Merchan'!Z16*'SwapDesk — Assumptions · Mercha'!D6 -> 2363.1814
A20: Verified arrangements | B20: =SUM('SwapDesk — Operations · Merchan'!B21,'SwapDesk — Operations · Merchan'!B22) -> 0 | C20: =SUM('SwapDesk — Operations · Merchan'!C21,'SwapDesk — Operations · Merchan'!C22) -> 1095.9 | D20: =SUM('SwapDesk — Operations · Merchan'!D21,'SwapDesk — Operations · Merchan'!D22) -> 1277.419 | E20: =SUM('SwapDesk — Operations · Merchan'!E21,'SwapDesk — Operations · Merchan'!E22) -> 1454.6645 | F20: =SUM('SwapDesk — Operations · Merchan'!F21,'SwapDesk — Operations · Merchan'!F22) -> 1627.7413 | G20: =SUM('SwapDesk — Operations · Merchan'!G21,'SwapDesk — Operations · Merchan'!G22) -> 1796.7514 | H20: =SUM('SwapDesk — Operations · Merchan'!H21,'SwapDesk — Operations · Merchan'!H22) -> 1961.7944 | I20: =SUM('SwapDesk — Operations · Merchan'!I21,'SwapDesk — Operations · Merchan'!I22) -> 2122.9672 | ... Z20: =SUM('SwapDesk — Operations · Merchan'!Z21,'SwapDesk — Operations · Merchan'!Z22) -> 4353.7015
A21: Growing shop | B21: =0 -> 0 | C21: ='SwapDesk — Operations · Merchan'!C18*'SwapDesk — Assumptions · Mercha'!E5 -> 639.6 | D21: ='SwapDesk — Operations · Merchan'!D18*'SwapDesk — Assumptions · Mercha'!E5 -> 756.808 | E21: ='SwapDesk — Operations · Merchan'!E18*'SwapDesk — Assumptions · Mercha'!E5 -> 871.67184 | F21: ='SwapDesk — Operations · Merchan'!F18*'SwapDesk — Assumptions · Mercha'!E5 -> 984.2384 | G21: ='SwapDesk — Operations · Merchan'!G18*'SwapDesk — Assumptions · Mercha'!E5 -> 1094.5536 | H21: ='SwapDesk — Operations · Merchan'!H18*'SwapDesk — Assumptions · Mercha'!E5 -> 1202.6626 | I21: ='SwapDesk — Operations · Merchan'!I18*'SwapDesk — Assumptions · Mercha'!E5 -> 1308.6093 | J21: ='SwapDesk — Operations · Merchan'!J18*'SwapDesk — Assumptions · Mercha'!E5 -> 1412.4371 | K21: ='SwapDesk — Operations · Merchan'!K18*'SwapDesk — Assumptions · Mercha'!E5 -> 1514.1884 | L21: ='SwapDesk — Operations · Merchan'!L18*'SwapDesk — Assumptions · Mercha'!E5 -> 1613.9046 | M21: ='SwapDesk — Operations · Merchan'!M18*'SwapDesk — Assumptions · Mercha'!E5 -> 1711.6265 | N21: ='SwapDesk — Operations · Merchan'!N18*'SwapDesk — Assumptions · Mercha'!E5 -> 1807.394 | O21: ='SwapDesk — Operations · Merchan'!O18*'SwapDesk — Assumptions · Mercha'!E5 -> 1901.2461 | P21: ='SwapDesk — Operations · Merchan'!P18*'SwapDesk — Assumptions · Mercha'!E5 -> 1993.2212 | Q21: ='SwapDesk — Operations · Merchan'!Q18*'SwapDesk — Assumptions · Mercha'!E5 -> 2083.3568 | R21: ='SwapDesk — Operations · Merchan'!R18*'SwapDesk — Assumptions · Mercha'!E5 -> 2171.6896 | S21: ='SwapDesk — Operations · Merchan'!S18*'SwapDesk — Assumptions · Mercha'!E5 -> 2258.2558 | T21: ='SwapDesk — Operations · Merchan'!T18*'SwapDesk — Assumptions · Mercha'!E5 -> 2343.0907 | U21: ='SwapDesk — Operations · Merchan'!U18*'SwapDesk — Assumptions · Mercha'!E5 -> 2426.2289 | V21: ='SwapDesk — Operations · Merchan'!V18*'SwapDesk — Assumptions · Mercha'!E5 -> 2507.7043 | W21: ='SwapDesk — Operations · Merchan'!W18*'SwapDesk — Assumptions · Mercha'!E5 -> 2587.5502 | X21: ='SwapDesk — Operations · Merchan'!X18*'SwapDesk — Assumptions · Mercha'!E5 -> 2665.7992 | Y21: ='SwapDesk — Operations · Merchan'!Y18*'SwapDesk — Assumptions · Mercha'!E5 -> 2742.4833 | Z21: ='SwapDesk — Operations · Merchan'!Z18*'SwapDesk — Assumptions · Mercha'!E5 -> 2817.6336
A22: Small shop | B22: =0 -> 0 | C22: ='SwapDesk — Operations · Merchan'!C19*'SwapDesk — Assumptions · Mercha'!E6 -> 456.3 | D22: ='SwapDesk — Operations · Merchan'!D19*'SwapDesk — Assumptions · Mercha'!E6 -> 520.611 | E22: ='SwapDesk — Operations · Merchan'!E19*'SwapDesk — Assumptions · Mercha'!E6 -> 582.99267 | F22: ='SwapDesk — Operations · Merchan'!F19*'SwapDesk — Assumptions · Mercha'!E6 -> 643.50289 | G22: ='SwapDesk — Operations · Merchan'!G19*'SwapDesk — Assumptions · Mercha'!E6 -> 702.1978 | H22: ='SwapDesk — Operations · Merchan'!H19*'SwapDesk — Assumptions · Mercha'!E6 -> 759.13187 | I22: ='SwapDesk — Operations · Merchan'!I19*'SwapDesk — Assumptions · Mercha'!E6 -> 814.35791 | J22: ='SwapDesk — Operations · Merchan'!J19*'SwapDesk — Assumptions · Mercha'!E6 -> 867.92718 | K22: ='SwapDesk — Operations · Merchan'!K19*'SwapDesk — Assumptions · Mercha'!E6 -> 919.88936 | L22: ='SwapDesk — Operations · Merchan'!L19*'SwapDesk — Assumptions · Mercha'!E6 -> 970.29268 | M22: ='SwapDesk — Operations · Merchan'!M19*'SwapDesk — Assumptions · Mercha'!E6 -> 1019.1839 | N22: ='SwapDesk — Operations · Merchan'!N19*'SwapDesk — Assumptions · Mercha'!E6 -> 1066.6084 | O22: ='SwapDesk — Operations · Merchan'!O19*'SwapDesk — Assumptions · Mercha'!E6 -> 1112.6101 | P22: ='SwapDesk — Operations · Merchan'!P19*'SwapDesk — Assumptions · Mercha'!E6 -> 1157.2318 | Q22: ='SwapDesk — Operations · Merchan'!Q19*'SwapDesk — Assumptions · Mercha'!E6 -> 1200.5149 | R22: ='SwapDesk — Operations · Merchan'!R19*'SwapDesk — Assumptions · Mercha'!E6 -> 1242.4994 | S22: ='SwapDesk — Operations · Merchan'!S19*'SwapDesk — Assumptions · Mercha'!E6 -> 1283.2244 | T22: ='SwapDesk — Operations · Merchan'!T19*'SwapDesk — Assumptions · Mercha'!E6 -> 1322.7277 | U22: ='SwapDesk — Operations · Merchan'!U19*'SwapDesk — Assumptions · Mercha'!E6 -> 1361.0459 | V22: ='SwapDesk — Operations · Merchan'!V19*'SwapDesk — Assumptions · Mercha'!E6 -> 1398.2145 | W22: ='SwapDesk — Operations · Merchan'!W19*'SwapDesk — Assumptions · Mercha'!E6 -> 1434.2681 | X22: ='SwapDesk — Operations · Merchan'!X19*'SwapDesk — Assumptions · Mercha'!E6 -> 1469.24 | Y22: ='SwapDesk — Operations · Merchan'!Y19*'SwapDesk — Assumptions · Mercha'!E6 -> 1503.1628 | Z22: ='SwapDesk — Operations · Merchan'!Z19*'SwapDesk — Assumptions · Mercha'!E6 -> 1536.0679
A23: Nonbillable cases | B23: =SUM('SwapDesk — Operations · Merchan'!B24,'SwapDesk — Operations · Merchan'!B25) -> 0 | C23: =SUM('SwapDesk — Operations · Merchan'!C24,'SwapDesk — Operations · Merchan'!C25) -> 590.1 | D23: =SUM('SwapDesk — Operations · Merchan'!D24,'SwapDesk — Operations · Merchan'!D25) -> 687.841 | E23: =SUM('SwapDesk — Operations · Merchan'!E24,'SwapDesk — Operations · Merchan'!E25) -> 783.28089 | F23: =SUM('SwapDesk — Operations · Merchan'!F24,'SwapDesk — Operations · Merchan'!F25) -> 876.47608 | G23: =SUM('SwapDesk — Operations · Merchan'!G24,'SwapDesk — Operations · Merchan'!G25) -> 967.48154 | H23: =SUM('SwapDesk — Operations · Merchan'!H24,'SwapDesk — Operations · Merchan'!H25) -> 1056.3508 | I23: =SUM('SwapDesk — Operations · Merchan'!I24,'SwapDesk — Operations · Merchan'!I25) -> 1143.1362 | ... Z23: =SUM('SwapDesk — Operations · Merchan'!Z24,'SwapDesk — Operations · Merchan'!Z25) -> 2344.3008
A24: Growing shop | B24: =0 -> 0 | C24: ='SwapDesk — Operations · Merchan'!C18-'SwapDesk — Operations · Merchan'!C21 -> 344.4 | D24: ='SwapDesk — Operations · Merchan'!D18-'SwapDesk — Operations · Merchan'!D21 -> 407.512 | E24: ='SwapDesk — Operations · Merchan'!E18-'SwapDesk — Operations · Merchan'!E21 -> 469.36176 | F24: ='SwapDesk — Operations · Merchan'!F18-'SwapDesk — Operations · Merchan'!F21 -> 529.97452 | G24: ='SwapDesk — Operations · Merchan'!G18-'SwapDesk — Operations · Merchan'!G21 -> 589.37503 | H24: ='SwapDesk — Operations · Merchan'!H18-'SwapDesk — Operations · Merchan'!H21 -> 647.58753 | I24: ='SwapDesk — Operations · Merchan'!I18-'SwapDesk — Operations · Merchan'!I21 -> 704.63578 | J24: ='SwapDesk — Operations · Merchan'!J18-'SwapDesk — Operations · Merchan'!J21 -> 760.54307 | ... Z24: ='SwapDesk — Operations · Merchan'!Z18-'SwapDesk — Operations · Merchan'!Z21 -> 1517.1873
A25: Small shop | B25: =0 -> 0 | C25: ='SwapDesk — Operations · Merchan'!C19-'SwapDesk — Operations · Merchan'!C22 -> 245.7 | D25: ='SwapDesk — Operations · Merchan'!D19-'SwapDesk — Operations · Merchan'!D22 -> 280.329 | E25: ='SwapDesk — Operations · Merchan'!E19-'SwapDesk — Operations · Merchan'!E22 -> 313.91913 | F25: ='SwapDesk — Operations · Merchan'!F19-'SwapDesk — Operations · Merchan'!F22 -> 346.50156 | G25: ='SwapDesk — Operations · Merchan'!G19-'SwapDesk — Operations · Merchan'!G22 -> 378.10651 | H25: ='SwapDesk — Operations · Merchan'!H19-'SwapDesk — Operations · Merchan'!H22 -> 408.76331 | I25: ='SwapDesk — Operations · Merchan'!I19-'SwapDesk — Operations · Merchan'!I22 -> 438.50041 | J25: ='SwapDesk — Operations · Merchan'!J19-'SwapDesk — Operations · Merchan'!J22 -> 467.3454 | ... Z25: ='SwapDesk — Operations · Merchan'!Z19-'SwapDesk — Operations · Merchan'!Z22 -> 827.11351
A26: Extra executions | B26: =SUM('SwapDesk — Operations · Merchan'!B27,'SwapDesk — Operations · Merchan'!B28) -> 0 | C26: =SUM('SwapDesk — Operations · Merchan'!C27,'SwapDesk — Operations · Merchan'!C28) -> 252.9 | D26: =SUM('SwapDesk — Operations · Merchan'!D27,'SwapDesk — Operations · Merchan'!D28) -> 294.789 | E26: =SUM('SwapDesk — Operations · Merchan'!E27,'SwapDesk — Operations · Merchan'!E28) -> 335.69181 | F26: =SUM('SwapDesk — Operations · Merchan'!F27,'SwapDesk — Operations · Merchan'!F28) -> 375.63261 | G26: =SUM('SwapDesk — Operations · Merchan'!G27,'SwapDesk — Operations · Merchan'!G28) -> 414.63495 | H26: =SUM('SwapDesk — Operations · Merchan'!H27,'SwapDesk — Operations · Merchan'!H28) -> 452.72179 | I26: =SUM('SwapDesk — Operations · Merchan'!I27,'SwapDesk — Operations · Merchan'!I28) -> 489.91551 | ... Z26: =SUM('SwapDesk — Operations · Merchan'!Z27,'SwapDesk — Operations · Merchan'!Z28) -> 1004.7004
A27: Growing shop | B27: =0 -> 0 | C27: ='SwapDesk — Operations · Merchan'!C18*'SwapDesk — Assumptions · Mercha'!F5 -> 147.6 | D27: ='SwapDesk — Operations · Merchan'!D18*'SwapDesk — Assumptions · Mercha'!F5 -> 174.648 | E27: ='SwapDesk — Operations · Merchan'!E18*'SwapDesk — Assumptions · Mercha'!F5 -> 201.15504 | F27: ='SwapDesk — Operations · Merchan'!F18*'SwapDesk — Assumptions · Mercha'!F5 -> 227.13194 | G27: ='SwapDesk — Operations · Merchan'!G18*'SwapDesk — Assumptions · Mercha'!F5 -> 252.5893 | H27: ='SwapDesk — Operations · Merchan'!H18*'SwapDesk — Assumptions · Mercha'!F5 -> 277.53751 | I27: ='SwapDesk — Operations · Merchan'!I18*'SwapDesk — Assumptions · Mercha'!F5 -> 301.98676 | J27: ='SwapDesk — Operations · Merchan'!J18*'SwapDesk — Assumptions · Mercha'!F5 -> 325.94703 | K27: ='SwapDesk — Operations · Merchan'!K18*'SwapDesk — Assumptions · Mercha'!F5 -> 349.42809 | L27: ='SwapDesk — Operations · Merchan'!L18*'SwapDesk — Assumptions · Mercha'!F5 -> 372.43953 | M27: ='SwapDesk — Operations · Merchan'!M18*'SwapDesk — Assumptions · Mercha'!F5 -> 394.99074 | N27: ='SwapDesk — Operations · Merchan'!N18*'SwapDesk — Assumptions · Mercha'!F5 -> 417.09092 | O27: ='SwapDesk — Operations · Merchan'!O18*'SwapDesk — Assumptions · Mercha'!F5 -> 438.7491 | P27: ='SwapDesk — Operations · Merchan'!P18*'SwapDesk — Assumptions · Mercha'!F5 -> 459.97412 | Q27: ='SwapDesk — Operations · Merchan'!Q18*'SwapDesk — Assumptions · Mercha'!F5 -> 480.77464 | R27: ='SwapDesk — Operations · Merchan'!R18*'SwapDesk — Assumptions · Mercha'!F5 -> 501.15915 | S27: ='SwapDesk — Operations · Merchan'!S18*'SwapDesk — Assumptions · Mercha'!F5 -> 521.13596 | T27: ='SwapDesk — Operations · Merchan'!T18*'SwapDesk — Assumptions · Mercha'!F5 -> 540.71324 | U27: ='SwapDesk — Operations · Merchan'!U18*'SwapDesk — Assumptions · Mercha'!F5 -> 559.89898 | V27: ='SwapDesk — Operations · Merchan'!V18*'SwapDesk — Assumptions · Mercha'!F5 -> 578.701 | W27: ='SwapDesk — Operations · Merchan'!W18*'SwapDesk — Assumptions · Mercha'!F5 -> 597.12698 | X27: ='SwapDesk — Operations · Merchan'!X18*'SwapDesk — Assumptions · Mercha'!F5 -> 615.18444 | Y27: ='SwapDesk — Operations · Merchan'!Y18*'SwapDesk — Assumptions · Mercha'!F5 -> 632.88075 | Z27: ='SwapDesk — Operations · Merchan'!Z18*'SwapDesk — Assumptions · Mercha'!F5 -> 650.22314
A28: Small shop | B28: =0 -> 0 | C28: ='SwapDesk — Operations · Merchan'!C19*'SwapDesk — Assumptions · Mercha'!F6 -> 105.3 | D28: ='SwapDesk — Operations · Merchan'!D19*'SwapDesk — Assumptions · Mercha'!F6 -> 120.141 | E28: ='SwapDesk — Operations · Merchan'!E19*'SwapDesk — Assumptions · Mercha'!F6 -> 134.53677 | F28: ='SwapDesk — Operations · Merchan'!F19*'SwapDesk — Assumptions · Mercha'!F6 -> 148.50067 | G28: ='SwapDesk — Operations · Merchan'!G19*'SwapDesk — Assumptions · Mercha'!F6 -> 162.04565 | H28: ='SwapDesk — Operations · Merchan'!H19*'SwapDesk — Assumptions · Mercha'!F6 -> 175.18428 | I28: ='SwapDesk — Operations · Merchan'!I19*'SwapDesk — Assumptions · Mercha'!F6 -> 187.92875 | J28: ='SwapDesk — Operations · Merchan'!J19*'SwapDesk — Assumptions · Mercha'!F6 -> 200.29089 | K28: ='SwapDesk — Operations · Merchan'!K19*'SwapDesk — Assumptions · Mercha'!F6 -> 212.28216 | L28: ='SwapDesk — Operations · Merchan'!L19*'SwapDesk — Assumptions · Mercha'!F6 -> 223.9137 | M28: ='SwapDesk — Operations · Merchan'!M19*'SwapDesk — Assumptions · Mercha'!F6 -> 235.19628 | N28: ='SwapDesk — Operations · Merchan'!N19*'SwapDesk — Assumptions · Mercha'!F6 -> 246.1404 | O28: ='SwapDesk — Operations · Merchan'!O19*'SwapDesk — Assumptions · Mercha'!F6 -> 256.75618 | P28: ='SwapDesk — Operations · Merchan'!P19*'SwapDesk — Assumptions · Mercha'!F6 -> 267.0535 | Q28: ='SwapDesk — Operations · Merchan'!Q19*'SwapDesk — Assumptions · Mercha'!F6 -> 277.04189 | R28: ='SwapDesk — Operations · Merchan'!R19*'SwapDesk — Assumptions · Mercha'!F6 -> 286.73064 | S28: ='SwapDesk — Operations · Merchan'!S19*'SwapDesk — Assumptions · Mercha'!F6 -> 296.12872 | T28: ='SwapDesk — Operations · Merchan'!T19*'SwapDesk — Assumptions · Mercha'!F6 -> 305.24486 | U28: ='SwapDesk — Operations · Merchan'!U19*'SwapDesk — Assumptions · Mercha'!F6 -> 314.08751 | V28: ='SwapDesk — Operations · Merchan'!V19*'SwapDesk — Assumptions · Mercha'!F6 -> 322.66489 | W28: ='SwapDesk — Operations · Merchan'!W19*'SwapDesk — Assumptions · Mercha'!F6 -> 330.98494 | X28: ='SwapDesk — Operations · Merchan'!X19*'SwapDesk — Assumptions · Mercha'!F6 -> 339.05539 | Y28: ='SwapDesk — Operations · Merchan'!Y19*'SwapDesk — Assumptions · Mercha'!F6 -> 346.88373 | Z28: ='SwapDesk — Operations · Merchan'!Z19*'SwapDesk — Assumptions · Mercha'!F6 -> 354.47722
A29: Total executions | B29: =SUM('SwapDesk — Operations · Merchan'!B30,'SwapDesk — Operations · Merchan'!B31) -> 0 | C29: =SUM('SwapDesk — Operations · Merchan'!C30,'SwapDesk — Operations · Merchan'!C31) -> 1938.9 | D29: =SUM('SwapDesk — Operations · Merchan'!D30,'SwapDesk — Operations · Merchan'!D31) -> 2260.049 | E29: =SUM('SwapDesk — Operations · Merchan'!E30,'SwapDesk — Operations · Merchan'!E31) -> 2573.6372 | F29: =SUM('SwapDesk — Operations · Merchan'!F30,'SwapDesk — Operations · Merchan'!F31) -> 2879.85 | G29: =SUM('SwapDesk — Operations · Merchan'!G30,'SwapDesk — Operations · Merchan'!G31) -> 3178.8679 | H29: =SUM('SwapDesk — Operations · Merchan'!H30,'SwapDesk — Operations · Merchan'!H31) -> 3470.8671 | I29: =SUM('SwapDesk — Operations · Merchan'!I30,'SwapDesk — Operations · Merchan'!I31) -> 3756.0189 | ... Z29: =SUM('SwapDesk — Operations · Merchan'!Z30,'SwapDesk — Operations · Merchan'!Z31) -> 7702.7027
A30: Growing shop | B30: =0 -> 0 | C30: ='SwapDesk — Operations · Merchan'!C18+'SwapDesk — Operations · Merchan'!C27 -> 1131.6 | D30: ='SwapDesk — Operations · Merchan'!D18+'SwapDesk — Operations · Merchan'!D27 -> 1338.968 | E30: ='SwapDesk — Operations · Merchan'!E18+'SwapDesk — Operations · Merchan'!E27 -> 1542.1886 | F30: ='SwapDesk — Operations · Merchan'!F18+'SwapDesk — Operations · Merchan'!F27 -> 1741.3449 | G30: ='SwapDesk — Operations · Merchan'!G18+'SwapDesk — Operations · Merchan'!G27 -> 1936.518 | H30: ='SwapDesk — Operations · Merchan'!H18+'SwapDesk — Operations · Merchan'!H27 -> 2127.7876 | I30: ='SwapDesk — Operations · Merchan'!I18+'SwapDesk — Operations · Merchan'!I27 -> 2315.2319 | J30: ='SwapDesk — Operations · Merchan'!J18+'SwapDesk — Operations · Merchan'!J27 -> 2498.9272 | ... Z30: ='SwapDesk — Operations · Merchan'!Z18+'SwapDesk — Operations · Merchan'!Z27 -> 4985.044
A31: Small shop | B31: =0 -> 0 | C31: ='SwapDesk — Operations · Merchan'!C19+'SwapDesk — Operations · Merchan'!C28 -> 807.3 | D31: ='SwapDesk — Operations · Merchan'!D19+'SwapDesk — Operations · Merchan'!D28 -> 921.081 | E31: ='SwapDesk — Operations · Merchan'!E19+'SwapDesk — Operations · Merchan'!E28 -> 1031.4486 | F31: ='SwapDesk — Operations · Merchan'!F19+'SwapDesk — Operations · Merchan'!F28 -> 1138.5051 | G31: ='SwapDesk — Operations · Merchan'!G19+'SwapDesk — Operations · Merchan'!G28 -> 1242.35 | H31: ='SwapDesk — Operations · Merchan'!H19+'SwapDesk — Operations · Merchan'!H28 -> 1343.0795 | I31: ='SwapDesk — Operations · Merchan'!I19+'SwapDesk — Operations · Merchan'!I28 -> 1440.7871 | J31: ='SwapDesk — Operations · Merchan'!J19+'SwapDesk — Operations · Merchan'!J28 -> 1535.5635 | ... Z31: ='SwapDesk — Operations · Merchan'!Z19+'SwapDesk — Operations · Merchan'!Z28 -> 2717.6587
A32: Subscription revenue | B32: =SUM('SwapDesk — Operations · Merchan'!B33,'SwapDesk — Operations · Merchan'!B34) -> 0 | C32: =SUM('SwapDesk — Operations · Merchan'!C33,'SwapDesk — Operations · Merchan'!C34) -> 407.19 | D32: =SUM('SwapDesk — Operations · Merchan'!D33,'SwapDesk — Operations · Merchan'!D34) -> 469.6797 | E32: =SUM('SwapDesk — Operations · Merchan'!E33,'SwapDesk — Operations · Merchan'!E34) -> 530.5156 | F32: =SUM('SwapDesk — Operations · Merchan'!F33,'SwapDesk — Operations · Merchan'!F34) -> 589.7429 | G32: =SUM('SwapDesk — Operations · Merchan'!G33,'SwapDesk — Operations · Merchan'!G34) -> 647.40552 | H32: =SUM('SwapDesk — Operations · Merchan'!H33,'SwapDesk — Operations · Merchan'!H34) -> 703.54617 | I32: =SUM('SwapDesk — Operations · Merchan'!I33,'SwapDesk — Operations · Merchan'!I34) -> 758.20634 | ... Z32: =SUM('SwapDesk — Operations · Merchan'!Z33,'SwapDesk — Operations · Merchan'!Z34) -> 1495.9813
A33: Growing shop | B33: =0 -> 0 | C33: ='SwapDesk — Operations · Merchan'!C15*'SwapDesk — Assumptions · Commer'!B5 -> 120.54 | D33: ='SwapDesk — Operations · Merchan'!D15*'SwapDesk — Assumptions · Commer'!B5 -> 142.6292 | E33: ='SwapDesk — Operations · Merchan'!E15*'SwapDesk — Assumptions · Commer'!B5 -> 164.27662 | F33: ='SwapDesk — Operations · Merchan'!F15*'SwapDesk — Assumptions · Commer'!B5 -> 185.49108 | G33: ='SwapDesk — Operations · Merchan'!G15*'SwapDesk — Assumptions · Commer'!B5 -> 206.28126 | H33: ='SwapDesk — Operations · Merchan'!H15*'SwapDesk — Assumptions · Commer'!B5 -> 226.65564 | I33: ='SwapDesk — Operations · Merchan'!I15*'SwapDesk — Assumptions · Commer'!B5 -> 246.62252 | J33: ='SwapDesk — Operations · Merchan'!J15*'SwapDesk — Assumptions · Commer'!B5 -> 266.19007 | K33: ='SwapDesk — Operations · Merchan'!K15*'SwapDesk — Assumptions · Commer'!B5 -> 285.36627 | L33: ='SwapDesk — Operations · Merchan'!L15*'SwapDesk — Assumptions · Commer'!B5 -> 304.15895 | M33: ='SwapDesk — Operations · Merchan'!M15*'SwapDesk — Assumptions · Commer'!B5 -> 322.57577 | N33: ='SwapDesk — Operations · Merchan'!N15*'SwapDesk — Assumptions · Commer'!B5 -> 340.62425 | O33: ='SwapDesk — Operations · Merchan'!O15*'SwapDesk — Assumptions · Commer'!B5 -> 358.31177 | P33: ='SwapDesk — Operations · Merchan'!P15*'SwapDesk — Assumptions · Commer'!B5 -> 375.64553 | Q33: ='SwapDesk — Operations · Merchan'!Q15*'SwapDesk — Assumptions · Commer'!B5 -> 392.63262 | R33: ='SwapDesk — Operations · Merchan'!R15*'SwapDesk — Assumptions · Commer'!B5 -> 409.27997 | S33: ='SwapDesk — Operations · Merchan'!S15*'SwapDesk — Assumptions · Commer'!B5 -> 425.59437 | T33: ='SwapDesk — Operations · Merchan'!T15*'SwapDesk — Assumptions · Commer'!B5 -> 441.58248 | U33: ='SwapDesk — Operations · Merchan'!U15*'SwapDesk — Assumptions · Commer'!B5 -> 457.25083 | V33: ='SwapDesk — Operations · Merchan'!V15*'SwapDesk — Assumptions · Commer'!B5 -> 472.60582 | W33: ='SwapDesk — Operations · Merchan'!W15*'SwapDesk — Assumptions · Commer'!B5 -> 487.6537 | X33: ='SwapDesk — Operations · Merchan'!X15*'SwapDesk — Assumptions · Commer'!B5 -> 502.40063 | Y33: ='SwapDesk — Operations · Merchan'!Y15*'SwapDesk — Assumptions · Commer'!B5 -> 516.85261 | Z33: ='SwapDesk — Operations · Merchan'!Z15*'SwapDesk — Assumptions · Commer'!B5 -> 531.01556
A34: Small shop | B34: =0 -> 0 | C34: ='SwapDesk — Operations · Merchan'!C16*'SwapDesk — Assumptions · Commer'!B5 -> 286.65 | D34: ='SwapDesk — Operations · Merchan'!D16*'SwapDesk — Assumptions · Commer'!B5 -> 327.0505 | E34: ='SwapDesk — Operations · Merchan'!E16*'SwapDesk — Assumptions · Commer'!B5 -> 366.23899 | F34: ='SwapDesk — Operations · Merchan'!F16*'SwapDesk — Assumptions · Commer'!B5 -> 404.25182 | G34: ='SwapDesk — Operations · Merchan'!G16*'SwapDesk — Assumptions · Commer'!B5 -> 441.12426 | H34: ='SwapDesk — Operations · Merchan'!H16*'SwapDesk — Assumptions · Commer'!B5 -> 476.89053 | I34: ='SwapDesk — Operations · Merchan'!I16*'SwapDesk — Assumptions · Commer'!B5 -> 511.58382 | J34: ='SwapDesk — Operations · Merchan'!J16*'SwapDesk — Assumptions · Commer'!B5 -> 545.2363 | K34: ='SwapDesk — Operations · Merchan'!K16*'SwapDesk — Assumptions · Commer'!B5 -> 577.87921 | L34: ='SwapDesk — Operations · Merchan'!L16*'SwapDesk — Assumptions · Commer'!B5 -> 609.54284 | M34: ='SwapDesk — Operations · Merchan'!M16*'SwapDesk — Assumptions · Commer'!B5 -> 640.25655 | N34: ='SwapDesk — Operations · Merchan'!N16*'SwapDesk — Assumptions · Commer'!B5 -> 670.04886 | O34: ='SwapDesk — Operations · Merchan'!O16*'SwapDesk — Assumptions · Commer'!B5 -> 698.94739 | P34: ='SwapDesk — Operations · Merchan'!P16*'SwapDesk — Assumptions · Commer'!B5 -> 726.97897 | Q34: ='SwapDesk — Operations · Merchan'!Q16*'SwapDesk — Assumptions · Commer'!B5 -> 754.1696 | R34: ='SwapDesk — Operations · Merchan'!R16*'SwapDesk — Assumptions · Commer'!B5 -> 780.54451 | S34: ='SwapDesk — Operations · Merchan'!S16*'SwapDesk — Assumptions · Commer'!B5 -> 806.12818 | T34: ='SwapDesk — Operations · Merchan'!T16*'SwapDesk — Assumptions · Commer'!B5 -> 830.94433 | U34: ='SwapDesk — Operations · Merchan'!U16*'SwapDesk — Assumptions · Commer'!B5 -> 855.016 | V34: ='SwapDesk — Operations · Merchan'!V16*'SwapDesk — Assumptions · Commer'!B5 -> 878.36552 | W34: ='SwapDesk — Operations · Merchan'!W16*'SwapDesk — Assumptions · Commer'!B5 -> 901.01455 | X34: ='SwapDesk — Operations · Merchan'!X16*'SwapDesk — Assumptions · Commer'!B5 -> 922.98412 | Y34: ='SwapDesk — Operations · Merchan'!Y16*'SwapDesk — Assumptions · Commer'!B5 -> 944.29459 | Z34: ='SwapDesk — Operations · Merchan'!Z16*'SwapDesk — Assumptions · Commer'!B5 -> 964.96576
A35: Overage revenue | B35: =SUM('SwapDesk — Operations · Merchan'!B36,'SwapDesk — Operations · Merchan'!B37) -> 0 | C35: =SUM('SwapDesk — Operations · Merchan'!C36,'SwapDesk — Operations · Merchan'!C37) -> 196.8 | D35: =SUM('SwapDesk — Operations · Merchan'!D36,'SwapDesk — Operations · Merchan'!D37) -> 232.864 | E35: =SUM('SwapDesk — Operations · Merchan'!E36,'SwapDesk — Operations · Merchan'!E37) -> 268.20672 | F35: =SUM('SwapDesk — Operations · Merchan'!F36,'SwapDesk — Operations · Merchan'!F37) -> 302.84259 | G35: =SUM('SwapDesk — Operations · Merchan'!G36,'SwapDesk — Operations · Merchan'!G37) -> 336.78573 | H35: =SUM('SwapDesk — Operations · Merchan'!H36,'SwapDesk — Operations · Merchan'!H37) -> 370.05002 | I35: =SUM('SwapDesk — Operations · Merchan'!I36,'SwapDesk — Operations · Merchan'!I37) -> 402.64902 | ... Z35: =SUM('SwapDesk — Operations · Merchan'!Z36,'SwapDesk — Operations · Merchan'!Z37) -> 866.96418
A36: Growing shop | B36: =0 -> 0 | C36: ='SwapDesk — Operations · Merchan'!C15*MAX('SwapDesk — Assumptions · Mercha'!D5*'SwapDesk — Assumptions · Mercha'!E5-'SwapDesk — Assumptions · Commer'!B6,0)*'SwapDesk — Assumptions · Commer'!B7 -> 196.8 | D36: ='SwapDesk — Operations · Merchan'!D15*MAX('SwapDesk — Assumptions · Mercha'!D5*'SwapDesk — Assumptions · Mercha'!E5-'SwapDesk — Assumptions · Commer'!B6,0)*'SwapDesk — Assumptions · Commer'!B7 -> 232.864 | E36: ='SwapDesk — Operations · Merchan'!E15*MAX('SwapDesk — Assumptions · Mercha'!D5*'SwapDesk — Assumptions · Mercha'!E5-'SwapDesk — Assumptions · Commer'!B6,0)*'SwapDesk — Assumptions · Commer'!B7 -> 268.20672 | F36: ='SwapDesk — Operations · Merchan'!F15*MAX('SwapDesk — Assumptions · Mercha'!D5*'SwapDesk — Assumptions · Mercha'!E5-'SwapDesk — Assumptions · Commer'!B6,0)*'SwapDesk — Assumptions · Commer'!B7 -> 302.84259 | G36: ='SwapDesk — Operations · Merchan'!G15*MAX('SwapDesk — Assumptions · Mercha'!D5*'SwapDesk — Assumptions · Mercha'!E5-'SwapDesk — Assumptions · Commer'!B6,0)*'SwapDesk — Assumptions · Commer'!B7 -> 336.78573 | H36: ='SwapDesk — Operations · Merchan'!H15*MAX('SwapDesk — Assumptions · Mercha'!D5*'SwapDesk — Assumptions · Mercha'!E5-'SwapDesk — Assumptions · Commer'!B6,0)*'SwapDesk — Assumptions · Commer'!B7 -> 370.05002 | I36: ='SwapDesk — Operations · Merchan'!I15*MAX('SwapDesk — Assumptions · Mercha'!D5*'SwapDesk — Assumptions · Mercha'!E5-'SwapDesk — Assumptions · Commer'!B6,0)*'SwapDesk — Assumptions · Commer'!B7 -> 402.64902 | J36: ='SwapDesk — Operations · Merchan'!J15*MAX('SwapDesk — Assumptions · Mercha'!D5*'SwapDesk — Assumptions · Mercha'!E5-'SwapDesk — Assumptions · Commer'!B6,0)*'SwapDesk — Assumptions · Commer'!B7 -> 434.59604 | K36: ='SwapDesk — Operations · Merchan'!K15*MAX('SwapDesk — Assumptions · Mercha'!D5*'SwapDesk — Assumptions · Mercha'!E5-'SwapDesk — Assumptions · Commer'!B6,0)*'SwapDesk — Assumptions · Commer'!B7 -> 465.90412 | L36: ='SwapDesk — Operations · Merchan'!L15*MAX('SwapDesk — Assumptions · Mercha'!D5*'SwapDesk — Assumptions · Mercha'!E5-'SwapDesk — Assumptions · Commer'!B6,0)*'SwapDesk — Assumptions · Commer'!B7 -> 496.58604 | M36: ='SwapDesk — Operations · Merchan'!M15*MAX('SwapDesk — Assumptions · Mercha'!D5*'SwapDesk — Assumptions · Mercha'!E5-'SwapDesk — Assumptions · Commer'!B6,0)*'SwapDesk — Assumptions · Commer'!B7 -> 526.65431 | N36: ='SwapDesk — Operations · Merchan'!N15*MAX('SwapDesk — Assumptions · Mercha'!D5*'SwapDesk — Assumptions · Mercha'!E5-'SwapDesk — Assumptions · Commer'!B6,0)*'SwapDesk — Assumptions · Commer'!B7 -> 556.12123 | O36: ='SwapDesk — Operations · Merchan'!O15*MAX('SwapDesk — Assumptions · Mercha'!D5*'SwapDesk — Assumptions · Mercha'!E5-'SwapDesk — Assumptions · Commer'!B6,0)*'SwapDesk — Assumptions · Commer'!B7 -> 584.9988 | P36: ='SwapDesk — Operations · Merchan'!P15*MAX('SwapDesk — Assumptions · Mercha'!D5*'SwapDesk — Assumptions · Mercha'!E5-'SwapDesk — Assumptions · Commer'!B6,0)*'SwapDesk — Assumptions · Commer'!B7 -> 613.29883 | Q36: ='SwapDesk — Operations · Merchan'!Q15*MAX('SwapDesk — Assumptions · Mercha'!D5*'SwapDesk — Assumptions · Mercha'!E5-'SwapDesk — Assumptions · Commer'!B6,0)*'SwapDesk — Assumptions · Commer'!B7 -> 641.03285 | R36: ='SwapDesk — Operations · Merchan'!R15*MAX('SwapDesk — Assumptions · Mercha'!D5*'SwapDesk — Assumptions · Mercha'!E5-'SwapDesk — Assumptions · Commer'!B6,0)*'SwapDesk — Assumptions · Commer'!B7 -> 668.21219 | S36: ='SwapDesk — Operations · Merchan'!S15*MAX('SwapDesk — Assumptions · Mercha'!D5*'SwapDesk — Assumptions · Mercha'!E5-'SwapDesk — Assumptions · Commer'!B6,0)*'SwapDesk — Assumptions · Commer'!B7 -> 694.84795 | T36: ='SwapDesk — Operations · Merchan'!T15*MAX('SwapDesk — Assumptions · Mercha'!D5*'SwapDesk — Assumptions · Mercha'!E5-'SwapDesk — Assumptions · Commer'!B6,0)*'SwapDesk — Assumptions · Commer'!B7 -> 720.95099 | U36: ='SwapDesk — Operations · Merchan'!U15*MAX('SwapDesk — Assumptions · Mercha'!D5*'SwapDesk — Assumptions · Mercha'!E5-'SwapDesk — Assumptions · Commer'!B6,0)*'SwapDesk — Assumptions · Commer'!B7 -> 746.53197 | V36: ='SwapDesk — Operations · Merchan'!V15*MAX('SwapDesk — Assumptions · Mercha'!D5*'SwapDesk — Assumptions · Mercha'!E5-'SwapDesk — Assumptions · Commer'!B6,0)*'SwapDesk — Assumptions · Commer'!B7 -> 771.60133 | W36: ='SwapDesk — Operations · Merchan'!W15*MAX('SwapDesk — Assumptions · Mercha'!D5*'SwapDesk — Assumptions · Mercha'!E5-'SwapDesk — Assumptions · Commer'!B6,0)*'SwapDesk — Assumptions · Commer'!B7 -> 796.16931 | X36: ='SwapDesk — Operations · Merchan'!X15*MAX('SwapDesk — Assumptions · Mercha'!D5*'SwapDesk — Assumptions · Mercha'!E5-'SwapDesk — Assumptions · Commer'!B6,0)*'SwapDesk — Assumptions · Commer'!B7 -> 820.24592 | Y36: ='SwapDesk — Operations · Merchan'!Y15*MAX('SwapDesk — Assumptions · Mercha'!D5*'SwapDesk — Assumptions · Mercha'!E5-'SwapDesk — Assumptions · Commer'!B6,0)*'SwapDesk — Assumptions · Commer'!B7 -> 843.841 | Z36: ='SwapDesk — Operations · Merchan'!Z15*MAX('SwapDesk — Assumptions · Mercha'!D5*'SwapDesk — Assumptions · Mercha'!E5-'SwapDesk — Assumptions · Commer'!B6,0)*'SwapDesk — Assumptions · Commer'!B7 -> 866.96418
A37: Small shop | B37: =0 -> 0 | C37: ='SwapDesk — Operations · Merchan'!C16*MAX('SwapDesk — Assumptions · Mercha'!D6*'SwapDesk — Assumptions · Mercha'!E6-'SwapDesk — Assumptions · Commer'!B6,0)*'SwapDesk — Assumptions · Commer'!B7 -> 0 | D37: ='SwapDesk — Operations · Merchan'!D16*MAX('SwapDesk — Assumptions · Mercha'!D6*'SwapDesk — Assumptions · Mercha'!E6-'SwapDesk — Assumptions · Commer'!B6,0)*'SwapDesk — Assumptions · Commer'!B7 -> 0 | E37: ='SwapDesk — Operations · Merchan'!E16*MAX('SwapDesk — Assumptions · Mercha'!D6*'SwapDesk — Assumptions · Mercha'!E6-'SwapDesk — Assumptions · Commer'!B6,0)*'SwapDesk — Assumptions · Commer'!B7 -> 0 | F37: ='SwapDesk — Operations · Merchan'!F16*MAX('SwapDesk — Assumptions · Mercha'!D6*'SwapDesk — Assumptions · Mercha'!E6-'SwapDesk — Assumptions · Commer'!B6,0)*'SwapDesk — Assumptions · Commer'!B7 -> 0 | G37: ='SwapDesk — Operations · Merchan'!G16*MAX('SwapDesk — Assumptions · Mercha'!D6*'SwapDesk — Assumptions · Mercha'!E6-'SwapDesk — Assumptions · Commer'!B6,0)*'SwapDesk — Assumptions · Commer'!B7 -> 0 | H37: ='SwapDesk — Operations · Merchan'!H16*MAX('SwapDesk — Assumptions · Mercha'!D6*'SwapDesk — Assumptions · Mercha'!E6-'SwapDesk — Assumptions · Commer'!B6,0)*'SwapDesk — Assumptions · Commer'!B7 -> 0 | I37: ='SwapDesk — Operations · Merchan'!I16*MAX('SwapDesk — Assumptions · Mercha'!D6*'SwapDesk — Assumptions · Mercha'!E6-'SwapDesk — Assumptions · Commer'!B6,0)*'SwapDesk — Assumptions · Commer'!B7 -> 0 | J37: ='SwapDesk — Operations · Merchan'!J16*MAX('SwapDesk — Assumptions · Mercha'!D6*'SwapDesk — Assumptions · Mercha'!E6-'SwapDesk — Assumptions · Commer'!B6,0)*'SwapDesk — Assumptions · Commer'!B7 -> 0 | K37: ='SwapDesk — Operations · Merchan'!K16*MAX('SwapDesk — Assumptions · Mercha'!D6*'SwapDesk — Assumptions · Mercha'!E6-'SwapDesk — Assumptions · Commer'!B6,0)*'SwapDesk — Assumptions · Commer'!B7 -> 0 | L37: ='SwapDesk — Operations · Merchan'!L16*MAX('SwapDesk — Assumptions · Mercha'!D6*'SwapDesk — Assumptions · Mercha'!E6-'SwapDesk — Assumptions · Commer'!B6,0)*'SwapDesk — Assumptions · Commer'!B7 -> 0 | M37: ='SwapDesk — Operations · Merchan'!M16*MAX('SwapDesk — Assumptions · Mercha'!D6*'SwapDesk — Assumptions · Mercha'!E6-'SwapDesk — Assumptions · Commer'!B6,0)*'SwapDesk — Assumptions · Commer'!B7 -> 0 | N37: ='SwapDesk — Operations · Merchan'!N16*MAX('SwapDesk — Assumptions · Mercha'!D6*'SwapDesk — Assumptions · Mercha'!E6-'SwapDesk — Assumptions · Commer'!B6,0)*'SwapDesk — Assumptions · Commer'!B7 -> 0 | O37: ='SwapDesk — Operations · Merchan'!O16*MAX('SwapDesk — Assumptions · Mercha'!D6*'SwapDesk — Assumptions · Mercha'!E6-'SwapDesk — Assumptions · Commer'!B6,0)*'SwapDesk — Assumptions · Commer'!B7 -> 0 | P37: ='SwapDesk — Operations · Merchan'!P16*MAX('SwapDesk — Assumptions · Mercha'!D6*'SwapDesk — Assumptions · Mercha'!E6-'SwapDesk — Assumptions · Commer'!B6,0)*'SwapDesk — Assumptions · Commer'!B7 -> 0 | Q37: ='SwapDesk — Operations · Merchan'!Q16*MAX('SwapDesk — Assumptions · Mercha'!D6*'SwapDesk — Assumptions · Mercha'!E6-'SwapDesk — Assumptions · Commer'!B6,0)*'SwapDesk — Assumptions · Commer'!B7 -> 0 | R37: ='SwapDesk — Operations · Merchan'!R16*MAX('SwapDesk — Assumptions · Mercha'!D6*'SwapDesk — Assumptions · Mercha'!E6-'SwapDesk — Assumptions · Commer'!B6,0)*'SwapDesk — Assumptions · Commer'!B7 -> 0 | S37: ='SwapDesk — Operations · Merchan'!S16*MAX('SwapDesk — Assumptions · Mercha'!D6*'SwapDesk — Assumptions · Mercha'!E6-'SwapDesk — Assumptions · Commer'!B6,0)*'SwapDesk — Assumptions · Commer'!B7 -> 0 | T37: ='SwapDesk — Operations · Merchan'!T16*MAX('SwapDesk — Assumptions · Mercha'!D6*'SwapDesk — Assumptions · Mercha'!E6-'SwapDesk — Assumptions · Commer'!B6,0)*'SwapDesk — Assumptions · Commer'!B7 -> 0 | U37: ='SwapDesk — Operations · Merchan'!U16*MAX('SwapDesk — Assumptions · Mercha'!D6*'SwapDesk — Assumptions · Mercha'!E6-'SwapDesk — Assumptions · Commer'!B6,0)*'SwapDesk — Assumptions · Commer'!B7 -> 0 | V37: ='SwapDesk — Operations · Merchan'!V16*MAX('SwapDesk — Assumptions · Mercha'!D6*'SwapDesk — Assumptions · Mercha'!E6-'SwapDesk — Assumptions · Commer'!B6,0)*'SwapDesk — Assumptions · Commer'!B7 -> 0 | W37: ='SwapDesk — Operations · Merchan'!W16*MAX('SwapDesk — Assumptions · Mercha'!D6*'SwapDesk — Assumptions · Mercha'!E6-'SwapDesk — Assumptions · Commer'!B6,0)*'SwapDesk — Assumptions · Commer'!B7 -> 0 | X37: ='SwapDesk — Operations · Merchan'!X16*MAX('SwapDesk — Assumptions · Mercha'!D6*'SwapDesk — Assumptions · Mercha'!E6-'SwapDesk — Assumptions · Commer'!B6,0)*'SwapDesk — Assumptions · Commer'!B7 -> 0 | Y37: ='SwapDesk — Operations · Merchan'!Y16*MAX('SwapDesk — Assumptions · Mercha'!D6*'SwapDesk — Assumptions · Mercha'!E6-'SwapDesk — Assumptions · Commer'!B6,0)*'SwapDesk — Assumptions · Commer'!B7 -> 0 | Z37: ='SwapDesk — Operations · Merchan'!Z16*MAX('SwapDesk — Assumptions · Mercha'!D6*'SwapDesk — Assumptions · Mercha'!E6-'SwapDesk — Assumptions · Commer'!B6,0)*'SwapDesk — Assumptions · Commer'!B7 -> 0
A38: Revenue | B38: =SUM('SwapDesk — Operations · Merchan'!B39,'SwapDesk — Operations · Merchan'!B40) -> 0 | C38: =SUM('SwapDesk — Operations · Merchan'!C39,'SwapDesk — Operations · Merchan'!C40) -> 603.99 | D38: =SUM('SwapDesk — Operations · Merchan'!D39,'SwapDesk — Operations · Merchan'!D40) -> 702.5437 | E38: =SUM('SwapDesk — Operations · Merchan'!E39,'SwapDesk — Operations · Merchan'!E40) -> 798.72232 | F38: =SUM('SwapDesk — Operations · Merchan'!F39,'SwapDesk — Operations · Merchan'!F40) -> 892.58548 | G38: =SUM('SwapDesk — Operations · Merchan'!G39,'SwapDesk — Operations · Merchan'!G40) -> 984.19126 | H38: =SUM('SwapDesk — Operations · Merchan'!H39,'SwapDesk — Operations · Merchan'!H40) -> 1073.5962 | I38: =SUM('SwapDesk — Operations · Merchan'!I39,'SwapDesk — Operations · Merchan'!I40) -> 1160.8554 | ... Z38: =SUM('SwapDesk — Operations · Merchan'!Z39,'SwapDesk — Operations · Merchan'!Z40) -> 2362.9455
